Workbook

Sheet Full Roster
A1: Sale Rep ID | B1: Full Contact ID | C1: First Name | D1: Last Name | E1: Full Name | F1: Representative Category | G1: YJ Category | H1: Active | I1: Sales team | J1: Phone Number | K1: Email | L1: Company - Job | M1: 25-26 Dollars | N1: Future Class | O1: In SF
A2: 2041793 | B2: 0031Y0000637jKFQAY | C2: Bob | D2: Aggarwal | E2: Bob Aggarwal | F2: Yellow Jacket | G2: Committee Member | H2: TRUE | I2: Peter the Anteater | J2: 480-323-0560 | K2: baggarwal@alliancebankofarizona.com | L2: Alliance Bank-VP Commercial Banking | M2: {=XLOOKUP(C2&D2, 'Yellow Jacket Fundraising 25-26'!$A$2:$A$112 & 'Yellow Jacket Fundraising 25-26'!$B$2:$B$112, 'Yellow Jacket Fundraising 25-26'!$G$2:$G$112, "Not Found")} -> 20112 | N2: 2021-22 | O2: =vlookup(B2,'SF Roster'!A:G,7,false) -> Committee Member
A3: 2138132 | C3: Daniel | D3: Akmon | E3: Daniel Akmon | F3: Yellow Jacket | G3: Future | H3: TRUE | I3: Fightin' Artichokes | J3: (602) 361-4600 | K3: Daniel.akmon@claconnect.com | L3: CLA-Principal | M3: {=XLOOKUP(C3&D3, 'Yellow Jacket Fundraising 25-26'!$A$2:$A$112 & 'Yellow Jacket Fundraising 25-26'!$B$2:$B$112, 'Yellow Jacket Fundraising 25-26'!$G$2:$G$112, "Not Found")} -> Future | N3: 2026-27 | O3: =vlookup(B3,'SF Roster'!A:G,7,false) -> #N/A
A4: 2041775 | B4: 0031Y0000637jiWQAQ | C4: Jonathan | D4: Amato | E4: Jonathan Amato | F4: Yellow Jacket | G4: Committee Member | H4: TRUE | I4: Blue Hose | J4: 914-494-3179 | K4: jonathan.amato@westin.com | L4: The Westin Kierland Resort & Spa - Director of Sales and Marketing | M4: {=XLOOKUP(C4&D4, 'Yellow Jacket Fundraising 25-26'!$A$2:$A$112 & 'Yellow Jacket Fundraising 25-26'!$B$2:$B$112, 'Yellow Jacket Fundraising 25-26'!$G$2:$G$112, "Not Found")} -> 46431 | N4: 2020-21 | O4: =vlookup(B4,'SF Roster'!A:G,7,false) -> Committee Member
A5: 93126 | B5: 0035d00006NTQsiAAH | C5: Jeffrey | D5: Anderson | E5: Jeffrey Anderson | F5: Yellow Jacket | G5: Committee Member | H5: TRUE | I5: Banana Slugs | J5: (602) 321-9660 | K5: Jeff.anderson@aleragroup.com | L5: BCG 401(k) Advisors - President | M5: {=XLOOKUP(C5&D5, 'Yellow Jacket Fundraising 25-26'!$A$2:$A$112 & 'Yellow Jacket Fundraising 25-26'!$B$2:$B$112, 'Yellow Jacket Fundraising 25-26'!$G$2:$G$112, "Not Found")} -> 39259 | N5: 2021-22 | O5: =vlookup(B5,'SF Roster'!A:G,7,false) -> Committee Member
A6: 2095489 | C6: Ray | D6: Artigue | E6: Ray Artigue | F6: Life Directors & Members | G6: Life Director | H6: TRUE | J6: N/A | K6: N/A | L6: N/A | M6: {=XLOOKUP(C6&D6, 'Yellow Jacket Fundraising 25-26'!$A$2:$A$112 & 'Yellow Jacket Fundraising 25-26'!$B$2:$B$112, 'Yellow Jacket Fundraising 25-26'!$G$2:$G$112, "Not Found")} -> Not Found | N6: N/A | O6: =vlookup(B6,'SF Roster'!A:G,7,false) -> #N/A
A7: 2138133 | C7: Chancellor | D7: Barjona | E7: Chancellor Barjona | F7: Yellow Jacket | G7: Future | H7: TRUE | I7: Peter the Anteater | J7: (480) 599-9198 | K7: chancellor.barjona@gmail.com | L7: IBM Principle Data & AI Leader - Financial Services | M7: {=XLOOKUP(C7&D7, 'Yellow Jacket Fundraising 25-26'!$A$2:$A$112 & 'Yellow Jacket Fundraising 25-26'!$B$2:$B$112, 'Yellow Jacket Fundraising 25-26'!$G$2:$G$112, "Not Found")} -> Future | N7: 2026-27 | O7: =vlookup(B7,'SF Roster'!A:G,7,false) -> #N/A
A8: 79594 | C8: Patrick | D8: Barkley | E8: Patrick Barkley | F8: Life Directors & Members | G8: Life Director | H8: TRUE | J8: N/A | K8: N/A | L8: N/A | M8: {=XLOOKUP(C8&D8, 'Yellow Jacket Fundraising 25-26'!$A$2:$A$112 & 'Yellow Jacket Fundraising 25-26'!$B$2:$B$112, 'Yellow Jacket Fundraising 25-26'!$G$2:$G$112, "Not Found")} -> Not Found | N8: N/A | O8: =vlookup(B8,'SF Roster'!A:G,7,false) -> #N/A
A9: 2041805 | B9: 003i000000HAUd8AAH | C9: Eric | D9: Barkyoumb | E9: Eric Barkyoumb | F9: Yellow Jacket | G9: Committee Member | H9: TRUE | I9: Dirtbags | J9: 480-209-7993 | K9: ebarkyoumb@gmail.com | L9: Dignity Health Foundation - Philanthropy Manager | M9: {=XLOOKUP(C9&D9, 'Yellow Jacket Fundraising 25-26'!$A$2:$A$112 & 'Yellow Jacket Fundraising 25-26'!$B$2:$B$112, 'Yellow Jacket Fundraising 25-26'!$G$2:$G$112, "Not Found")} -> 115548 | N9: 2012-13 | O9: =vlookup(B9,'SF Roster'!A:G,7,false) -> Committee Member
A10: 2095186 | C10: Brian | D10: Bednar | E10: Brian Bednar | F10: Board of Directors | G10: Board | H10: TRUE | J10: N/A | K10: N/A | L10: N/A | M10: {=XLOOKUP(C10&D10, 'Yellow Jacket Fundraising 25-26'!$A$2:$A$112 & 'Yellow Jacket Fundraising 25-26'!$B$2:$B$112, 'Yellow Jacket Fundraising 25-26'!$G$2:$G$112, "Not Found")} -> Not Found | N10: N/A | O10: =vlookup(B10,'SF Roster'!A:G,7,false) -> #N/A
A11: 2095195 | C11: Judy | D11: Bernas | E11: Judy Bernas | F11: Board of Directors | G11: Board | H11: TRUE | J11: N/A | K11: N/A | L11: N/A | M11: {=XLOOKUP(C11&D11, 'Yellow Jacket Fundraising 25-26'!$A$2:$A$112 & 'Yellow Jacket Fundraising 25-26'!$B$2:$B$112, 'Yellow Jacket Fundraising 25-26'!$G$2:$G$112, "Not Found")} -> Not Found | N11: N/A | O11: =vlookup(B11,'SF Roster'!A:G,7,false) -> #N/A
A12: 100553 | C12: Scott | D12: Bernstein | E12: Scott Bernstein | F12: Life Directors & Members | G12: Life Member | H12: TRUE | J12: N/A | K12: N/A | L12: N/A | M12: {=XLOOKUP(C12&D12, 'Yellow Jacket Fundraising 25-26'!$A$2:$A$112 & 'Yellow Jacket Fundraising 25-26'!$B$2:$B$112, 'Yellow Jacket Fundraising 25-26'!$G$2:$G$112, "Not Found")} -> Not Found | N12: N/A | O12: =vlookup(B12,'SF Roster'!A:G,7,false) -> #N/A
A13: 2041802 | C13: Bryan | D13: Beverly | E13: Bryan Beverly | F13: Life Directors & Members | G13: Life Member | H13: TRUE | J13: N/A | K13: N/A | L13: N/A | M13: {=XLOOKUP(C13&D13, 'Yellow Jacket Fundraising 25-26'!$A$2:$A$112 & 'Yellow Jacket Fundraising 25-26'!$B$2:$B$112, 'Yellow Jacket Fundraising 25-26'!$G$2:$G$112, "Not Found")} -> Not Found | N13: N/A | O13: =vlookup(B13,'SF Roster'!A:G,7,false) -> #N/A
A14: 2095193 | C14: Jeff | D14: Beyersdorfer | E14: Jeff Beyersdorfer | F14: Board of Directors | G14: Board | H14: TRUE | J14: N/A | K14: N/A | L14: N/A | M14: {=XLOOKUP(C14&D14, 'Yellow Jacket Fundraising 25-26'!$A$2:$A$112 & 'Yellow Jacket Fundraising 25-26'!$B$2:$B$112, 'Yellow Jacket Fundraising 25-26'!$G$2:$G$112, "Not Found")} -> Not Found | N14: N/A | O14: =vlookup(B14,'SF Roster'!A:G,7,false) -> #N/A
A15: 2041836 | B15: 0035d00006iGLA8AAO | C15: Warren | D15: Black | E15: Warren Black | F15: Yellow Jacket | G15: Committee Member | H15: TRUE | I15: Cobbers | J15: 480-285-8502 | K15: warren.c.black@outlook.com | L15: Merrill Lynch - Financial Advisor Senior Portfolio Advisor | M15: {=XLOOKUP(C15&D15, 'Yellow Jacket Fundraising 25-26'!$A$2:$A$112 & 'Yellow Jacket Fundraising 25-26'!$B$2:$B$112, 'Yellow Jacket Fundraising 25-26'!$G$2:$G$112, "Not Found")} -> 19523 | N15: 2022-23 | O15: =vlookup(B15,'SF Roster'!A:G,7,false) -> Committee Member
A16: 2044787 | C16: Lisa | D16: Borowsky | E16: Lisa Borowsky | F16: Yellow Jacket | H16: FALSE | J16: N/A | K16: N/A | L16: N/A | M16: {=XLOOKUP(C16&D16, 'Yellow Jacket Fundraising 25-26'!$A$2:$A$112 & 'Yellow Jacket Fundraising 25-26'!$B$2:$B$112, 'Yellow Jacket Fundraising 25-26'!$G$2:$G$112, "Not Found")} -> Not Found | N16: N/A | O16: =vlookup(B16,'SF Roster'!A:G,7,false) -> #N/A
A17: 2044788 | B17: 0035d0000793oC6AAI | C17: Bryan | D17: Boyer | E17: Bryan Boyer | F17: Yellow Jacket | G17: Committee Member | H17: TRUE | I17: Pistol Petes | J17: 480-267-4169 | K17: bboyer7740@gmail.com | L17: Avis/Budget Group - Business Development Manager | M17: {=XLOOKUP(C17&D17, 'Yellow Jacket Fundraising 25-26'!$A$2:$A$112 & 'Yellow Jacket Fundraising 25-26'!$B$2:$B$112, 'Yellow Jacket Fundraising 25-26'!$G$2:$G$112, "Not Found")} -> 8493 | N17: 2023-24 | O17: =vlookup(B17,'SF Roster'!A:G,7,false) -> Committee Member
A18: 2041858 | C18: Damon | D18: Boze | E18: Damon Boze | F18: Yellow Jacket | H18: FALSE | J18: N/A | K18: N/A | L18: N/A | M18: {=XLOOKUP(C18&D18, 'Yellow Jacket Fundraising 25-26'!$A$2:$A$112 & 'Yellow Jacket Fundraising 25-26'!$B$2:$B$112, 'Yellow Jacket Fundraising 25-26'!$G$2:$G$112, "Not Found")} -> Not Found | N18: N/A | O18: =vlookup(B18,'SF Roster'!A:G,7,false) -> #N/A
A19: 105682 | B19: 0035d00006iGLX7AAO | C19: Justin | D19: Bretag | E19: Justin Bretag | F19: Yellow Jacket | G19: Committee Member | H19: TRUE | I19: Fighting Pickles | J19: (602) 361-7027 | K19: Justin.bretag@busey.com | L19: Busey Bank-Managing Director Commercial | M19: {=XLOOKUP(C19&D19, 'Yellow Jacket Fundraising 25-26'!$A$2:$A$112 & 'Yellow Jacket Fundraising 25-26'!$B$2:$B$112, 'Yellow Jacket Fundraising 25-26'!$G$2:$G$112, "Not Found")} -> 50127 | N19: 2022-23 | O19: =vlookup(B19,'SF Roster'!A:G,7,false) -> Committee Member
A20: 97581 | C20: Robert | D20: Bridge | E20: Robert Bridge | F20: Life Directors & Members | G20: Life Member | H20: TRUE | J20: N/A | K20: N/A | L20: N/A | M20: {=XLOOKUP(C20&D20, 'Yellow Jacket Fundraising 25-26'!$A$2:$A$112 & 'Yellow Jacket Fundraising 25-26'!$B$2:$B$112, 'Yellow Jacket Fundraising 25-26'!$G$2:$G$112, "Not Found")} -> Not Found | N20: N/A | O20: =vlookup(B20,'SF Roster'!A:G,7,false) -> #N/A
A21: 2044789 | C21: Martyn | D21: Bridgeman | E21: Martyn Bridgeman | F21: Yellow Jacket | H21: FALSE | J21: N/A | K21: N/A | L21: N/A | M21: {=XLOOKUP(C21&D21, 'Yellow Jacket Fundraising 25-26'!$A$2:$A$112 & 'Yellow Jacket Fundraising 25-26'!$B$2:$B$112, 'Yellow Jacket Fundraising 25-26'!$G$2:$G$112, "Not Found")} -> Not Found | N21: N/A | O21: =vlookup(B21,'SF Roster'!A:G,7,false) -> #N/A
A22: 2044790 | B22: 0035d0000793o4ZAAQ | C22: Lindsey | D22: Brist | E22: Lindsey Brist | F22: Yellow Jacket | G22: Committee Member | H22: TRUE | I22: Stormy Petrels | J22: (208) 631-7601 | K22: lindsey.brist@mmrgrp.com | L22: MMR Constructors - Business Development Manager | M22: {=XLOOKUP(C22&D22, 'Yellow Jacket Fundraising 25-26'!$A$2:$A$112 & 'Yellow Jacket Fundraising 25-26'!$B$2:$B$112, 'Yellow Jacket Fundraising 25-26'!$G$2:$G$112, "Not Found")} -> 27359 | N22: 2023-24 | O22: =vlookup(B22,'SF Roster'!A:G,7,false) -> Committee Member
A23: 2095202 | C23: Tim | D23: Brown | E23: Tim Brown | F23: Board of Directors | G23: Board | H23: TRUE | J23: N/A | K23: N/A | L23: N/A | M23: {=XLOOKUP(C23&D23, 'Yellow Jacket Fundraising 25-26'!$A$2:$A$112 & 'Yellow Jacket Fundraising 25-26'!$B$2:$B$112, 'Yellow Jacket Fundraising 25-26'!$G$2:$G$112, "Not Found")} -> Not Found | N23: N/A | O23: =vlookup(B23,'SF Roster'!A:G,7,false) -> #N/A
A24: 2138142 | C24: Lisa | D24: Bullington | E24: Lisa Bullington | F24: Board of Directors | G24: Board | H24: TRUE | J24: N/A | K24: N/A | L24: N/A | M24: {=XLOOKUP(C24&D24, 'Yellow Jacket Fundraising 25-26'!$A$2:$A$112 & 'Yellow Jacket Fundraising 25-26'!$B$2:$B$112, 'Yellow Jacket Fundraising 25-26'!$G$2:$G$112, "Not Found")} -> Not Found | N24: N/A | O24: =vlookup(B24,'SF Roster'!A:G,7,false) -> #N/A
A25: 100695 | B25: 0031Y00005kTGeIQAW | C25: Taylor | D25: Burgoon | E25: Taylor Burgoon | F25: Yellow Jacket | G25: Committee Member | H25: TRUE | I25: Fightin' Artichokes | J25: 734-776-7362 | K25: tburgoon@fennemorelaw.com | L25: Fennemore Craig P.C. Attorney | M25: {=XLOOKUP(C25&D25, 'Yellow Jacket Fundraising 25-26'!$A$2:$A$112 & 'Yellow Jacket Fundraising 25-26'!$B$2:$B$112, 'Yellow Jacket Fundraising 25-26'!$G$2:$G$112, "Not Found")} -> 14319 | N25: 2019-20 | O25: =vlookup(B25,'SF Roster'!A:G,7,false) -> Committee Member
A26: 2041835 | B26: 0035d00006iGLXqAAO | C26: Benjamin | D26: Burke | E26: Benjamin Burke | F26: Yellow Jacket | G26: Committee Member | H26: TRUE | I26: Banana Slugs | J26: 608-385-4078 | K26: benburke@msn.com | L26: Van Wagner-Vice President College Division | M26: {=XLOOKUP(C26&D26, 'Yellow Jacket Fundraising 25-26'!$A$2:$A$112 & 'Yellow Jacket Fundraising 25-26'!$B$2:$B$112, 'Yellow Jacket Fundraising 25-26'!$G$2:$G$112, "Not Found")} -> 8158 | N26: 2022-23 | O26: =vlookup(B26,'SF Roster'!A:G,7,false) -> Committee Member
A27: 2138160 | C27: Tyler | D27: Butler | E27: Tyler Butler | F27: Yellow Jacket | G27: Future | H27: TRUE | I27: Dirtbags | J27: (480) 431-8580 | K27: connect@collaborationforgood.com | L27: Collaboration for Good Founder | M27: {=XLOOKUP(C27&D27, 'Yellow Jacket Fundraising 25-26'!$A$2:$A$112 & 'Yellow Jacket Fundraising 25-26'!$B$2:$B$112, 'Yellow Jacket Fundraising 25-26'!$G$2:$G$112, "Not Found")} -> Future | N27: 2026-27 | O27: =vlookup(B27,'SF Roster'!A:G,7,false) -> #N/A
A28: 2041837 | C28: Jake | D28: Butterfield | E28: Jake Butterfield | F28: Yellow Jacket | H28: FALSE | J28: N/A | K28: N/A | L28: N/A | M28: {=XLOOKUP(C28&D28, 'Yellow Jacket Fundraising 25-26'!$A$2:$A$112 & 'Yellow Jacket Fundraising 25-26'!$B$2:$B$112, 'Yellow Jacket Fundraising 25-26'!$G$2:$G$112, "Not Found")} -> Not Found | N28: N/A | O28: =vlookup(B28,'SF Roster'!A:G,7,false) -> #N/A
A29: 2095205 | C29: Greg | D29: Byrne | E29: Greg Byrne | F29: Board of Directors | G29: Board | H29: TRUE | J29: N/A | K29: N/A | L29: N/A | M29: {=XLOOKUP(C29&D29, 'Yellow Jacket Fundraising 25-26'!$A$2:$A$112 & 'Yellow Jacket Fundraising 25-26'!$B$2:$B$112, 'Yellow Jacket Fundraising 25-26'!$G$2:$G$112, "Not Found")} -> Not Found | N29: N/A | O29: =vlookup(B29,'SF Roster'!A:G,7,false) -> #N/A
A30: 2041838 | C30: Joe | D30: Cafferelli | E30: Joe Cafferelli | F30: Life Directors & Members | G30: Life Member | H30: TRUE | J30: N/A | K30: N/A | L30: N/A | M30: {=XLOOKUP(C30&D30, 'Yellow Jacket Fundraising 25-26'!$A$2:$A$112 & 'Yellow Jacket Fundraising 25-26'!$B$2:$B$112, 'Yellow Jacket Fundraising 25-26'!$G$2:$G$112, "Not Found")} -> Not Found | N30: N/A | O30: =vlookup(B30,'SF Roster'!A:G,7,false) -> #N/A
A31: 2062813 | B31: 003VX00000CeOJGYA3 | C31: Ben | D31: Calacci | E31: Ben Calacci | F31: Yellow Jacket | G31: Committee Member | H31: TRUE | I31: Banana Slugs | J31: (703) 967-7691 | K31: ben.calacci@gmail.com | L31: Team Velocity - Vice President OEM | M31: {=XLOOKUP(C31&D31, 'Yellow Jacket Fundraising 25-26'!$A$2:$A$112 & 'Yellow Jacket Fundraising 25-26'!$B$2:$B$112, 'Yellow Jacket Fundraising 25-26'!$G$2:$G$112, "Not Found")} -> 20034 | N31: 2024-25 | O31: =vlookup(B31,'SF Roster'!A:G,7,false) -> Committee Member
A32: 2041855 | C32: Grady | D32: Callaghan | E32: Grady Callaghan | F32: Yellow Jacket | H32: FALSE | J32: N/A | K32: N/A | L32: N/A | M32: {=XLOOKUP(C32&D32, 'Yellow Jacket Fundraising 25-26'!$A$2:$A$112 & 'Yellow Jacket Fundraising 25-26'!$B$2:$B$112, 'Yellow Jacket Fundraising 25-26'!$G$2:$G$112, "Not Found")} -> Not Found | N32: N/A | O32: =vlookup(B32,'SF Roster'!A:G,7,false) -> #N/A
A33: 2095088 | C33: Brett | D33: Callahan | E33: Brett Callahan | F33: Yellow Jacket | H33: FALSE | J33: N/A | K33: N/A | L33: N/A | M33: {=XLOOKUP(C33&D33, 'Yellow Jacket Fundraising 25-26'!$A$2:$A$112 & 'Yellow Jacket Fundraising 25-26'!$B$2:$B$112, 'Yellow Jacket Fundraising 25-26'!$G$2:$G$112, "Not Found")} -> Not Found | N33: N/A | O33: =vlookup(B33,'SF Roster'!A:G,7,false) -> #N/A
A34: 2041783 | C34: Jennifer | D34: Cannon | E34: Jennifer Cannon | F34: Life Directors & Members | G34: Life Member | H34: TRUE | J34: N/A | K34: N/A | L34: N/A | M34: {=XLOOKUP(C34&D34, 'Yellow Jacket Fundraising 25-26'!$A$2:$A$112 & 'Yellow Jacket Fundraising 25-26'!$B$2:$B$112, 'Yellow Jacket Fundraising 25-26'!$G$2:$G$112, "Not Found")} -> Not Found | N34: N/A | O34: =vlookup(B34,'SF Roster'!A:G,7,false) -> #N/A
A35: 101859 | C35: Gene | D35: Carl | E35: Gene Carl | F35: Life Directors & Members | G35: Life Member | H35: TRUE | J35: N/A | K35: N/A | L35: N/A | M35: {=XLOOKUP(C35&D35, 'Yellow Jacket Fundraising 25-26'!$A$2:$A$112 & 'Yellow Jacket Fundraising 25-26'!$B$2:$B$112, 'Yellow Jacket Fundraising 25-26'!$G$2:$G$112, "Not Found")} -> Not Found | N35: N/A | O35: =vlookup(B35,'SF Roster'!A:G,7,false) -> #N/A
A36: 2044792 | C36: Eric | D36: Caruth | E36: Eric Caruth | F36: Yellow Jacket | H36: FALSE | J36: N/A | K36: N/A | L36: N/A | M36: {=XLOOKUP(C36&D36, 'Yellow Jacket Fundraising 25-26'!$A$2:$A$112 & 'Yellow Jacket Fundraising 25-26'!$B$2:$B$112, 'Yellow Jacket Fundraising 25-26'!$G$2:$G$112, "Not Found")} -> Not Found | N36: N/A | O36: =vlookup(B36,'SF Roster'!A:G,7,false) -> #N/A
A37: 2044793 | C37: Izabela | D37: Castillo | E37: Izabela Castillo | F37: Yellow Jacket | H37: FALSE | J37: N/A | K37: N/A | L37: N/A | M37: {=XLOOKUP(C37&D37, 'Yellow Jacket Fundraising 25-26'!$A$2:$A$112 & 'Yellow Jacket Fundraising 25-26'!$B$2:$B$112, 'Yellow Jacket Fundraising 25-26'!$G$2:$G$112, "Not Found")} -> Not Found | N37: N/A | O37: =vlookup(B37,'SF Roster'!A:G,7,false) -> #N/A
A38: 2041857 | C38: John | D38: Craiger | E38: John Craiger | F38: Life Directors & Members | G38: Life Member | H38: TRUE | J38: N/A | K38: N/A | L38: N/A | M38: {=XLOOKUP(C38&D38, 'Yellow Jacket Fundraising 25-26'!$A$2:$A$112 & 'Yellow Jacket Fundraising 25-26'!$B$2:$B$112, 'Yellow Jacket Fundraising 25-26'!$G$2:$G$112, "Not Found")} -> Not Found | N38: N/A | O38: =vlookup(B38,'SF Roster'!A:G,7,false) -> #N/A
A39: 2041823 | C39: Walker | D39: Crowson | E39: Walker Crowson | F39: Life Directors & Members | G39: Life Member | H39: TRUE | J39: N/A | K39: N/A | L39: N/A | M39: {=XLOOKUP(C39&D39, 'Yellow Jacket Fundraising 25-26'!$A$2:$A$112 & 'Yellow Jacket Fundraising 25-26'!$B$2:$B$112, 'Yellow Jacket Fundraising 25-26'!$G$2:$G$112, "Not Found")} -> Not Found | N39: N/A | O39: =vlookup(B39,'SF Roster'!A:G,7,false) -> #N/A
A40: 2095089 | B40: 003VX00000YQJzdYAH | C40: Kerri | D40: Cummiskey | E40: Kerri Cummiskey | F40: Yellow Jacket | G40: Committee Member | H40: TRUE | I40: Cobbers | J40: (480) 435-5347 | K40: kerri.cummiskey@alumus.com | L40: Alumus Sr VP of Network Development and Strategic Partnerships | M40: {=XLOOKUP(C40&D40, 'Yellow Jacket Fundraising 25-26'!$A$2:$A$112 & 'Yellow Jacket Fundraising 25-26'!$B$2:$B$112, 'Yellow Jacket Fundraising 25-26'!$G$2:$G$112, "Not Found")} -> 11002 | N40: 2025-26 | O40: =vlookup(B40,'SF Roster'!A:G,7,false) -> Committee Member
...

Sheet SF Roster
A1: Full Contact ID | C1: First Name | D1: Last Name | E1: Yellow Jacket Team | F1: First Year of Volunteering | G1: Bowl Position
A2: 0031Y0000637jKFQAY | C2: Bob | D2: Aggarwal | E2: Fighting Pickles | F2: 2021 | G2: Committee Member
A3: 0031Y0000637jiWQAQ | C3: Jonathan | D3: Amato | E3: Blue Hose | F3: 2020 | G3: Committee Member
A4: 0035d00006NTQsiAAH | C4: Jeffrey | D4: Anderson | E4: Speedy the Geoduck | F4: 2021 | G4: Committee Member
A5: 003i000000HAUd8AAH | C5: Eric | D5: Barkyoumb | E5: Pistol Petes | F5: 2012 | G5: Committee Member
A6: 0035d00006iGLA8AAO | C6: Warren | D6: Black | E6: Peter the Anteater | F6: 2022 | G6: Committee Member
A7: 0035d0000793oC6AAI | C7: Bryan | D7: Boyer | E7: Fighting Pickles | F7: 2023 | G7: Committee Member
A8: 0035d00006iGLX7AAO | C8: Justin | D8: Bretag | E8: Peter the Anteater | F8: 2022 | G8: Committee Member
A9: 0035d0000793o4ZAAQ | C9: Lindsey | D9: Brist | E9: Gorlocks | F9: 2023 | G9: Committee Member
A10: 0031Y00005kTGeIQAW | C10: Taylor | D10: Burgoon | E10: Blue Hose | F10: 2019 | G10: Committee Member
A11: 0035d00006iGLXqAAO | C11: Benjamin | D11: Burke | E11: Blue Hose | F11: 2022 | G11: Committee Member
A12: 003VX00000CeOJGYA3 | C12: Ben | D12: Calacci | E12: Speedy the Geoduck | F12: 2024 | G12: Committee Member
... A52: 003i000002KdHH1AAN | C52: Kirk | D52: McClure | E52: Fighting Camels | F52: 2016 | G52: Committee Member
A53: 003VX00000voHuUYAU | C53: Sean | D53: McEvilly | G53: Fiesta Future
A54: 0035d00006NTR74AAH | C54: Kyle | D54: McMillian | E54: Speedy the Geoduck | F54: 2021 | G54: Committee Member
A55: 003VX00000YQPKAYA5 | C55: Damien | D55: Meyer | E55: Banana Slugs | F55: 2025 | G55: Committee Member
A56: 003i000001LGx5FAAT | C56: John | D56: Meza | E56: Gorlocks | F56: 2016 | G56: Committee Member
A57: 003VX00000CfFgvYAF | C57: Tim | D57: Miller | E57: Pistol Petes | F57: 2024 | G57: Committee Member
A58: 003i000000HAUduAAH | C58: Brian | D58: Moll | E58: Speedy the Geoduck | F58: 2011 | G58: Committee Member
A59: 003VX00000voZoBYAU | C59: Rogelio | D59: Monzon | G59: Fiesta Future
A60: 0031Y00005kTGlsQAG | C60: Brad | D60: Morin | E60: Fighting Camels | F60: 2019 | G60: Committee Member
A61: 0031Y00005GT8HTQA1 | C61: Justin | D61: Naber | E61: Stormy Petrels | F61: 2018 | G61: Committee Member
A62: 0035d00006NTR7JAAX | C62: Gary | D62: Naquin | E62: Stormy Petrels | F62: 2021 | G62: Committee Member
A63: 003VX00000YjxTPYAZ | C63: Will | D63: Nation | E63: Fighting Pickles | F63: 2025 | G63: Committee Member
A64: 0035d00006viTv5AAE | C64: Suzanne | D64: Nelson | E64: Fighting Pickles | F64: 2023 | G64: Committee Member
A65: 003VX00000CfAAzYAN | C65: Jameson | D65: Neuhoff | E65: Peter the Anteater | F65: 2024 | G65: Committee Member
A66: 003i000000HAUdAAAX | C66: Tim | D66: Newquist | E66: Stormy Petrels | F66: 2012 | G66: Committee Member
A67: 003VX00000CfG9xYAF | C67: Brian | D67: Nuestro | E67: Speedy the Geoduck | F67: 2024 | G67: Committee Member
A68: 0031Y0000637kLTQAY | C68: Jerry | D68: Pence | E68: Fighting Camels | F68: 2020 | G68: Committee Member
A69: 0035d0000793lYsAAI | C69: Ryan | D69: Penniman | E69: Dirtbags | F69: 2023 | G69: Committee Member
A70: 003i000000NFnzBAAT | C70: Kelly | D70: Peru | E70: Speedy the Geoduck | F70: 2013 | G70: Committee Member
A71: 0031Y0000637kLiQAI | C71: Shane | D71: Peterlin | E71: Banana Slugs | F71: 2021 | G71: Committee Member
... A88: 0031Y0000637kNoQAI | C88: Joe | D88: Strening | E88: Fighting Camels | F88: 2020 | G88: Committee Member
A89: 003VX00000vnkbPYAQ | C89: Scot | D89: Taggart | G89: Fiesta Future
A90: 0035d0000793iTlAAI | C90: David | D90: Tatko | E90: Stormy Petrels | F90: 2023 | G90: Committee Member
A91: 0035d00006iGLZ6AAO | C91: Danny | D91: Thielen | E91: Dirtbags | F91: 2022 | G91: Committee Member
A92: 0031Y0000637kQnQAI | C92: Oye | D92: Waddell | E92: Sammy the Slug | F92: 2022 | G92: Committee Member
A93: 0031Y00005GT8MYQA1 | C93: Sean | D93: Ward | E93: Cobbers | F93: 2018 | G93: Committee Member
A94: 003i000001O9C8PAAV | C94: Josh | D94: Wein | E94: Banana Slugs | F94: 2016 | G94: Committee Member
A95: 003i000000w9NxVAAU | C95: David | D95: Weissman | E95: Dirtbags | F95: 2014 | G95: Committee Member
...

Sheet Yellow Jacket Fundraising 25-26
A1: First name | B1: Last name | C1: Full Name | D1: Email | E1: Phone | F1: Job | G1: 25-26 Fundraising Dollars | H1: 25-26 Fundraising Rank | I1: Future Class
A2: Chip | B2: Pray | C2: Chip Pray | D2: charles.pray@mclanefs.com | E2: (480) 266-8583 | F2: McLane Company Inc. General Manager | G2: 261599 | H2: 2 | I2: 2022-23
A3: Tim | B3: Newquist | C3: Tim Newquist | D3: tim@newquistinvestments.com | E3: 480-577-0847 | F3: Newquist Investments - Owner/Real Estate Investor/Consultant | G3: 187484 | H3: 3 | I3: 2012-13
A4: Renee | B4: Higgs | C4: Renee Higgs | D4: reneejhiggs@gmail.com | E4: 425-802-8844 | F4: Salt River Project (SRP) - Sr. Marketing Strategist | G4: 132413 | H4: 4 | I4: 2022-23
A5: Josh | B5: Wein | C5: Josh Wein | D5: weintime@gmail.com | E5: 480-432-4771 | F5: Home Smart - Residential Real Estate Sales Professional | G5: 120306 | H5: 5 | I5: 2016-17
A6: Logan | B6: Senoski | C6: Logan Senoski | D6: Logan.Senoski@srpnet.com | E6: (505) 401-6399 | F6: Salt River Project (SRP) - Senior Project Origination Consultant | G6: 119909 | H6: 6 | I6: 2018-19
A7: Kyle | B7: McMillian | C7: Kyle McMillian | D7: kyle.mcmillian@umb.com | E7: 913-620-6577 | F7: UMB Bank-Senior VP Commercial Banking Officer | G7: 115875 | H7: 7 | I7: 2021-22
A8: Eric | B8: Barkyoumb | C8: Eric Barkyoumb | D8: ebarkyoumb@gmail.com | E8: 480-209-7993 | F8: Dignity Health Foundation - Philanthropy Manager | G8: 115548 | H8: 8 | I8: 2012-13
A9: Kirk | B9: McClure | C9: Kirk McClure | D9: kirk.mcclure@jedunn.com | E9: (480) 305-3902 | F9: JE Dunn Construction - Vice President | G9: 99540 | H9: 9 | I9: 2016-17
A10: Kirk | B10: Fonfara | C10: Kirk Fonfara | D10: kirkfonfara@gmail.com | E10: 602-615-9225 | F10: Chicago Title Agency Arizona - Commercial Sales Executive | G10: 96550 | H10: 10 | I10: 2018-19
A11: DJ | B11: Downs | C11: DJ Downs | D11: djdowns1@gmail.com | E11: (575) 430-1850 | F11: Barrett-Jackson - Sr. Director of Marketing | G11: 90000 | H11: 11 | I11: 2023-24
A12: Chad | B12: Hunter | C12: Chad Hunter | D12: chad.hunter@bmo.com | E12: (623) 824-9788 | F12: BMO Financial Group - Director Commercial Bank | G12: 86889 | H12: 12 | I12: 2023-24
A13: William | B13: Jaffe | C13: William Jaffe | D13: williamjaffe@gmail.com | E13: (520) 360-8820 | F13: Abrazo Biltmore Cardiology-Preventative Cardiologist | G13: 66195 | H13: 13 | I13: 2023-24
... A15: Melissa | B15: Stack | C15: Melissa Stack | D15: melvittone@gmail.com | E15: (815) 228-0560 | F15: Deloitte LLP-Sr. Manager Risk and Brand Protection | G15: 52104 | H15: 15 | I15: 2024-25
A16: Jonathan | B16: Levin | C16: Jonathan Levin | D16: jonathanhlevin@gmail.com | E16: 480-313-0141 | F16: Zeta Beta Tau Foundation - Vice President of Development | G16: 50378 | H16: 16 | I16: 39692
A17: Justin | B17: Bretag | C17: Justin Bretag | D17: Justin.bretag@busey.com | E17: (602) 361-7027 | F17: Busey Bank-Managing Director Commercial | G17: 50127 | H17: 17 | I17: 2022-23
A18: Rick | B18: Zieglowsky | C18: Rick Zieglowsky | D18: rick.zieglowsky@gmail.com | E18: 480-993-8707 | F18: American Arbitration Association - Vice President-Construction | G18: 46585 | H18: 18 | I18: 2022-23
A19: Jonathan | B19: Amato | C19: Jonathan Amato | D19: jonathan.amato@westin.com | E19: 914-494-3179 | F19: The Westin Kierland Resort & Spa - Director of Sales and Marketing | G19: 46431 | H19: 19 | I19: 2020-21
A20: Mike | B20: Lindsley | C20: Mike Lindsley | D20: mike@bfoxg.com | E20: 480-326-3120 | F20: BlueFox Group-Partner | G20: 42030 | H20: 20 | I20: 40878
A21: Samantha | B21: Spadaro | C21: Samantha Spadaro | D21: sspadaro113@gmail.com | E21: 2032495791 | G21: 41525 | H21: 21 | I21: 2022-23
A22: Jeffrey | B22: Anderson | C22: Jeffrey Anderson | D22: Jeff.anderson@aleragroup.com | E22: (602) 321-9660 | F22: BCG 401(k) Advisors - President | G22: 39259 | H22: 22 | I22: 2021-22
A23: Ryan | B23: Delaney | C23: Ryan Delaney | D23: ryan.delaney@busey.com | E23: 319-470-3845 | F23: Busey Bank - Senior VP Director of Middle Market Banking | G23: 38690 | H23: 23 | I23: 2020-21
A24: Tim | B24: Martin | C24: Tim Martin | D24: timmartin602@yahoo.com | E24: (602) 505-0052 | F24: Arizona Athletic Grounds - VP of Sales | G24: 37856 | H24: 25 | I24: 2023-24
A25: Josh | B25: Guinn | C25: Josh Guinn | D25: Jguinn@eidebailly.com | E25: (602) 320-9337 | F25: Eide Bailly- Director of Business Development | G25: 36085 | H25: 26 | I25: 2025-26
A26: Justin | B26: Naber | C26: Justin Naber | D26: jnaber@brixnational.com | E26: 480-487-7558 | F26: Brix Paving Northwest Inc. - VP of Business Development | G26: 36076 | H26: 27 | I26: 2018-19
A27: Gabriel | B27: Hartsell | C27: Gabriel Hartsell | D27: hartsell.gabriel@dorsey.com | E27: (239) 560-7778 | F27: Dorsey & Whitney-Attorney/Partner | G27: 35519 | H27: 28 | I27: 2023-24
A28: Richie | B28: Schmock | C28: Richie Schmock | D28: richard.schmock@gmail.com | E28: 602-402-6835 | F28: Rockefeller Capital Management- Sr. Vice President | G28: 30000 | H28: 30 | I28: 40087
A29: Andrew | B29: Western | C29: Andrew Western | D29: awestern@omiaw.com | E29: 602-329-3477 | F29: Osborn Maledon - Partner | G29: 29428 | H29: 31 | I29: 2014-15
A30: Justin | B30: Pierce | C30: Justin Pierce | D30: drjustinpierce@gmail.com | E30: (517) 214-2501 | F30: Valley Spinal Care/ Owner | G30: 29243 | H30: 32 | I30: 2025-26
A31: Lindsey | B31: Brist | C31: Lindsey Brist | D31: lindsey.brist@mmrgrp.com | E31: (208) 631-7601 | F31: MMR Constructors - Business Development Manager | G31: 27359 | H31: 33 | I31: 2023-24
A32: Brian | B32: Moll | C32: Brian Moll | D32: bkm2@cox.net | E32: (602) 741-7775 | F32: Dorsey & Whitney LLP - Partner | G32: 27020 | H32: 34 | I32: 40878
A33: Kyler | B33: Robinson | C33: Kyler Robinson | D33: krobinson@crestins.com | E33: (307) 421-9811 | F33: Crest Insurance Group Commercial Insurance Broker | G33: 24768 | H33: 35 | I33: 2024-25
A34: Adam | B34: Fielding | C34: Adam Fielding | D34: afielding821@gmail.com | E34: (256) 861-0850 | F34: Platinum Dermatology Partners - Chief Compliance Officer | G34: 22999 | H34: 36 | I34: 2022-23
A35: Kelly | B35: Peru | C35: Kelly Peru | D35: kellyperu22@gmail.com | E35: 480-330-4316 | F35: Yellow Jacket Committee Member | G35: 22922 | H35: 37 | I35: 2013-14
A36: Danny | B36: Thielen | C36: Danny Thielen | D36: daniel.m.thielen@gmail.com | E36: 602-3505881 | F36: Axon Enterprise - Strategic Account Executive | G36: 21190 | H36: 38 | I36: 2022-23
A37: David | B37: Weissman | C37: David Weissman | D37: diweissman@gmail.com | E37: 602-535-6303 | F37: Davis Miles - Partner | G37: 21112 | H37: 39 | I37: 2014-15
A38: Will | B38: Nation | C38: Will Nation | D38: wnation@mtbuilders.com | E38: (602) 980-2336 | F38: MT Builders - President | G38: 20975 | H38: 40 | I38: 2025-26
A39: Brian | B39: Debnam | C39: Brian Debnam | D39: bkdebnam@gmail.com | E39: (520) 990-7030 | F39: NIKE Inc-Director & Chief of Staff Global Footwear Product Creation | G39: 20642 | H39: 41 | I39: 2017-18
A40: Bob | B40: Aggarwal | C40: Bob Aggarwal | D40: baggarwal@alliancebankofarizona.com | E40: 480-323-0560 | F40: Alliance Bank-VP Commercial Banking | G40: 20112 | H40: 42 | I40: 2021-22
A41: Ben | B41: Calacci | C41: Ben Calacci | D41: ben.calacci@gmail.com | E41: (703) 967-7691 | F41: Team Velocity - Vice President OEM | G41: 20034 | H41: 43 | I41: 2024-25
...
